<?xml version="1.0"?>
<robot name="origins">

  <material name="green">
    <color rgba="0 1 0 1"/>
  </material>
  <material name="blue">
    <color rgba="0 0 0.8 1"/>
  </material>

  <link name="base_link">
    <visual>
      <geometry>
        <mesh filename="package://urdf_tutorial/meshes/frame_URDF-1.STL"/> 
      </geometry>
      <origin rpy="0.0 0 0" xyz="0 0 0.57207"/>
       <material name="green"/>
    </visual>
  </link>

  <link name="crane_boom">
    <visual>
      <geometry>
        <mesh filename="package://urdf_tutorial/meshes/boom_URDF.STL"/> 
      </geometry>
      <origin rpy="0 0 0" xyz="3.10836 0 0.06343"/>
      <material name="green"/>
    </visual>
  </link>

  <!-- <link name="tool_tip">
    <visual>
      <geometry>
        <box size="0.1 0.1 0.1"/>
      </geometry>
      <origin rpy="0 0 0" xyz="0.05 0 0"/>
      <material name="blue"/>
    </visual>
  </link> -->

  <joint name="base_to_crane_boom" type="revolute">
    <axis rpy="0 0 0" xyz="0 1 0"/>
    <parent link="base_link"/>
    <child link="crane_boom"/>
    <limit effort="1000.0" lower="0.3267" upper="-0.6948" velocity="0.5"/>
    <origin rpy="0 0 0" xyz="-0.56876 0 1.752"/>
  </joint>

  <!-- <joint name="tool_tip_joint" type="fixed">
    <parent link="crane_boom"/>
    <child link="tool_tip"/>
    <origin xyz="3.68 0 0"/>
  </joint> -->

</robot>
